<?xml version="1.0" ?>
<!-- Generated using onshape-to-robot -->
<!-- Onshape https://cad.onshape.com/documents/cafb9abbd5e1994699c8b820/w/cf07a0aff3b93e2702c91cfe/e/7542deabeddb0c95a5ea610b -->
<robot name="pingti_arm">
  <!-- Link base_link -->
  <link name="base_link">
    <inertial>
      <origin xyz="-3.10996e-06 0.0145714 0.0268193" rpy="0 0 0"/>
      <mass value="0.42363"/>
      <inertia ixx="0.000376425" ixy="-8.506e-09" ixz="4.7691e-08" iyy="0.000409372" iyz="-3.47731e-05" izz="0.000399556"/>
    </inertial>
    <!-- Part sts3215_base_yaw -->
    <visual>
      <origin xyz="-0 0.00496106 0.0461" rpy="0 -0 -1.5708"/>
      <geometry>
        <mesh filename="assets/sts3215_base_yaw.stl"/>
      </geometry>
      <material name="sts3215_base_yaw_material">
        <color rgba="0.627451 0.627451 0.627451 1"/>
      </material>
    </visual>
    <collision>
      <origin xyz="-0 0.00496106 0.0461" rpy="0 -0 -1.5708"/>
      <geometry>
        <mesh filename="assets/sts3215_base_yaw.stl"/>
      </geometry>
    </collision>
    <!-- Part base_link -->
    <visual>
      <origin xyz="-0 0.0336225 -0" rpy="1.5708 -0 0"/>
      <geometry>
        <mesh filename="assets/base_link.stl"/>
      </geometry>
      <material name="base_link_material">
        <color rgba="0.627451 0.627451 0.627451 1"/>
      </material>
    </visual>
    <collision>
      <origin xyz="-0 0.0336225 -0" rpy="1.5708 -0 0"/>
      <geometry>
        <mesh filename="assets/base_link.stl"/>
      </geometry>
    </collision>
  </link>
  <!-- Link base_yaw_link -->
  <link name="base_yaw_link">
    <inertial>
      <origin xyz="0.0335325 -2.38474e-05 0.0549808" rpy="0 0 0"/>
      <mass value="0.472148"/>
      <inertia ixx="0.000563468" ixy="-2.14752e-07" ixz="-9.80749e-06" iyy="0.000456881" iyz="-5.14401e-07" izz="0.000235252"/>
    </inertial>
    <!-- Part base_yaw_link -->
    <visual>
      <origin xyz="-0.0395021 0.00817395 -0.501565" rpy="1.5708 0 1.5708"/>
      <geometry>
        <mesh filename="assets/base_yaw_link.stl"/>
      </geometry>
      <material name="base_yaw_link_material">
        <color rgba="0.627451 0.627451 0.627451 1"/>
      </material>
    </visual>
    <collision>
      <origin xyz="-0.0395021 0.00817395 -0.501565" rpy="1.5708 0 1.5708"/>
      <geometry>
        <mesh filename="assets/base_yaw_link.stl"/>
      </geometry>
    </collision>
    <!-- Part sts3215_shoulder_pitch_1 -->
    <visual>
      <origin xyz="0.03305 0.0205987 0.0803" rpy="-1.5708 -1.5708 0"/>
      <geometry>
        <mesh filename="assets/sts3215_shoulder_pitch_1.stl"/>
      </geometry>
      <material name="sts3215_shoulder_pitch_1_material">
        <color rgba="0.627451 0.627451 0.627451 1"/>
      </material>
    </visual>
    <collision>
      <origin xyz="0.03305 0.0205987 0.0803" rpy="-1.5708 -1.5708 0"/>
      <geometry>
        <mesh filename="assets/sts3215_shoulder_pitch_1.stl"/>
      </geometry>
    </collision>
    <!-- Part sts3215_shoulder_pitch_2 -->
    <visual>
      <origin xyz="0.03305 -0.0205987 0.0803" rpy="1.5708 -1.5708 0"/>
      <geometry>
        <mesh filename="assets/sts3215_shoulder_pitch_2.stl"/>
      </geometry>
      <material name="sts3215_shoulder_pitch_2_material">
        <color rgba="0.627451 0.627451 0.627451 1"/>
      </material>
    </visual>
    <collision>
      <origin xyz="0.03305 -0.0205987 0.0803" rpy="1.5708 -1.5708 0"/>
      <geometry>
        <mesh filename="assets/sts3215_shoulder_pitch_2.stl"/>
      </geometry>
    </collision>
  </link>
  <!-- Link shoulder_link -->
  <link name="shoulder_link">
    <inertial>
      <origin xyz="0.00438798 0.143122 0.0408772" rpy="0 0 0"/>
      <mass value="0.840414"/>
      <inertia ixx="0.00640477" ixy="-0.000302754" ixz="8.20751e-07" iyy="0.000824677" iyz="5.51294e-06" izz="0.00579839"/>
    </inertial>
    <!-- Part sts3215_elbow_pitch_2 -->
    <visual>
      <origin xyz="0.0192 0.23165 0.0610856" rpy="0 -0 0"/>
      <geometry>
        <mesh filename="assets/sts3215_elbow_pitch_2.stl"/>
      </geometry>
      <material name="sts3215_elbow_pitch_2_material">
        <color rgba="0.627451 0.627451 0.627451 1"/>
      </material>
    </visual>
    <collision>
      <origin xyz="0.0192 0.23165 0.0610856" rpy="0 -0 0"/>
      <geometry>
        <mesh filename="assets/sts3215_elbow_pitch_2.stl"/>
      </geometry>
    </collision>
    <!-- Part sts3215_elbow_pitch_1 -->
    <visual>
      <origin xyz="0.0192 0.23165 0.0205584" rpy="-3.14159 -0 0"/>
      <geometry>
        <mesh filename="assets/sts3215_elbow_pitch_1.stl"/>
      </geometry>
      <material name="sts3215_elbow_pitch_1_material">
        <color rgba="0.627451 0.627451 0.627451 1"/>
      </material>
    </visual>
    <collision>
      <origin xyz="0.0192 0.23165 0.0205584" rpy="-3.14159 -0 0"/>
      <geometry>
        <mesh filename="assets/sts3215_elbow_pitch_1.stl"/>
      </geometry>
    </collision>
    <!-- Part shoulder_link -->
    <visual>
      <origin xyz="-0.0808503 -0.0575799 -0.123362" rpy="-1.5708 -1.5708 0"/>
      <geometry>
        <mesh filename="assets/shoulder_link.stl"/>
      </geometry>
      <material name="shoulder_link_material">
        <color rgba="0.627451 0.627451 0.627451 1"/>
      </material>
    </visual>
    <collision>
      <origin xyz="-0.0808503 -0.0575799 -0.123362" rpy="-1.5708 -1.5708 0"/>
      <geometry>
        <mesh filename="assets/shoulder_link.stl"/>
      </geometry>
    </collision>
  </link>
  <!-- Link wrist_mount_link -->
  <link name="wrist_mount_link">
    <inertial>
      <origin xyz="0.161316 -0.019442 0.0327241" rpy="0 0 0"/>
      <mass value="0.589063"/>
      <inertia ixx="0.000409688" ixy="0.000637538" ixz="-0.000189853" iyy="0.00569386" iyz="2.35929e-05" izz="0.00549264"/>
    </inertial>
    <!-- Part elbow_link -->
    <visual>
      <origin xyz="0.357427 -0.0111903 0.0182" rpy="3.14159 -0 3.01926"/>
      <geometry>
        <mesh filename="assets/elbow_link.stl"/>
      </geometry>
      <material name="elbow_link_material">
        <color rgba="0.627451 0.627451 0.627451 1"/>
      </material>
    </visual>
    <collision>
      <origin xyz="0.357427 -0.0111903 0.0182" rpy="3.14159 -0 3.01926"/>
      <geometry>
        <mesh filename="assets/elbow_link.stl"/>
      </geometry>
    </collision>
    <!-- Part sts3215_wrist_pitch -->
    <visual>
      <origin xyz="0.277128 -0.0320413 0.0337208" rpy="0 -0 -0.122333"/>
      <geometry>
        <mesh filename="assets/sts3215_wrist_pitch.stl"/>
      </geometry>
      <material name="sts3215_wrist_pitch_material">
        <color rgba="0.627451 0.627451 0.627451 1"/>
      </material>
    </visual>
    <collision>
      <origin xyz="0.277128 -0.0320413 0.0337208" rpy="0 -0 -0.122333"/>
      <geometry>
        <mesh filename="assets/sts3215_wrist_pitch.stl"/>
      </geometry>
    </collision>
    <!-- Part wrist_mount_link -->
    <visual>
      <origin xyz="0.212309 -0.0594336 0.0352708" rpy="-0 -0 3.01926"/>
      <geometry>
        <mesh filename="assets/wrist_mount_link.stl"/>
      </geometry>
      <material name="wrist_mount_link_material">
        <color rgba="0.627451 0.627451 0.627451 1"/>
      </material>
    </visual>
    <collision>
      <origin xyz="0.212309 -0.0594336 0.0352708" rpy="-0 -0 3.01926"/>
      <geometry>
        <mesh filename="assets/wrist_mount_link.stl"/>
      </geometry>
    </collision>
  </link>
  <!-- Link sts3215_wrist_roll -->
  <link name="sts3215_wrist_roll">
    <inertial>
      <origin xyz="0.0350884 -2.38786e-05 0.0266542" rpy="0 0 0"/>
      <mass value="0.176621"/>
      <inertia ixx="6.79293e-05" ixy="-1.46617e-07" ixz="-9.04184e-06" iyy="0.000107455" iyz="-3.8228e-08" izz="6.31134e-05"/>
    </inertial>
    <!-- Part wrist_link -->
    <visual>
      <origin xyz="0.028 0 0.0181" rpy="-0 -1.5708 0"/>
      <geometry>
        <mesh filename="assets/wrist_link.stl"/>
      </geometry>
      <material name="wrist_link_material">
        <color rgba="0.627451 0.627451 0.627451 1"/>
      </material>
    </visual>
    <collision>
      <origin xyz="0.028 0 0.0181" rpy="-0 -1.5708 0"/>
      <geometry>
        <mesh filename="assets/wrist_link.stl"/>
      </geometry>
    </collision>
    <!-- Part sts3215_wrist_roll -->
    <visual>
      <origin xyz="0.0422157 0 0.0310357" rpy="-0 1.5708 0"/>
      <geometry>
        <mesh filename="assets/sts3215_wrist_roll.stl"/>
      </geometry>
      <material name="sts3215_wrist_roll_material">
        <color rgba="0.627451 0.627451 0.627451 1"/>
      </material>
    </visual>
    <collision>
      <origin xyz="0.0422157 0 0.0310357" rpy="-0 1.5708 0"/>
      <geometry>
        <mesh filename="assets/sts3215_wrist_roll.stl"/>
      </geometry>
    </collision>
  </link>
  <!-- Link sts3215_gripper -->
  <link name="sts3215_gripper">
    <inertial>
      <origin xyz="-0.0083362 0.000411805 -0.0270116" rpy="0 0 0"/>
      <mass value="0.251542"/>
      <inertia ixx="0.000119292" ixy="-1.22013e-06" ixz="-2.40965e-05" iyy="0.00014947" iyz="-2.17225e-07" izz="9.40173e-05"/>
    </inertial>
    <!-- Part gripper_mount -->
    <visual>
      <origin xyz="0 0 0" rpy="-3.14159 0 0"/>
      <geometry>
        <mesh filename="assets/gripper_mount.stl"/>
      </geometry>
      <material name="gripper_mount_material">
        <color rgba="0.627451 0.627451 0.627451 1"/>
      </material>
    </visual>
    <collision>
      <origin xyz="0 0 0" rpy="-3.14159 0 0"/>
      <geometry>
        <mesh filename="assets/gripper_mount.stl"/>
      </geometry>
    </collision>
    <!-- Part sts3215_gripper -->
    <visual>
      <origin xyz="0.0005 0 -0.0234" rpy="-1.5708 0 0"/>
      <geometry>
        <mesh filename="assets/sts3215_gripper.stl"/>
      </geometry>
      <material name="sts3215_gripper_material">
        <color rgba="0.627451 0.627451 0.627451 1"/>
      </material>
    </visual>
    <collision>
      <origin xyz="0.0005 0 -0.0234" rpy="-1.5708 0 0"/>
      <geometry>
        <mesh filename="assets/sts3215_gripper.stl"/>
      </geometry>
    </collision>
  </link>
  <!-- Link moving_gripper -->
  <link name="moving_gripper">
    <inertial>
      <origin xyz="-0.000675865 -0.0299067 0.0192843" rpy="0 0 0"/>
      <mass value="0.0545806"/>
      <inertia ixx="2.98343e-05" ixy="-1.44153e-06" ixz="-2.8386e-08" iyy="8.15364e-06" iyz="-5.19572e-07" izz="2.42082e-05"/>
    </inertial>
    <!-- Part moving_gripper -->
    <visual>
      <origin xyz="0.000944164 0.000490603 0.0189" rpy="0 0 -0"/>
      <geometry>
        <mesh filename="assets/moving_gripper.stl"/>
      </geometry>
      <material name="moving_gripper_material">
        <color rgba="0.627451 0.627451 0.627451 1"/>
      </material>
    </visual>
    <collision>
      <origin xyz="0.000944164 0.000490603 0.0189" rpy="0 0 -0"/>
      <geometry>
        <mesh filename="assets/moving_gripper.stl"/>
      </geometry>
    </collision>
  </link>
  <!-- Joint from sts3215_gripper to moving_gripper -->
  <joint name="gripper_moving" type="revolute">
    <origin xyz="0.013 0.0198025 -0.0234" rpy="1.5708 0 0"/>
    <parent link="sts3215_gripper"/>
    <child link="moving_gripper"/>
    <axis xyz="0 0 1"/>
    <limit effort="10" velocity="10" lower="-0.0872665" upper="1.5708"/>
  </joint>
  <!-- Joint from sts3215_wrist_roll to sts3215_gripper -->
  <joint name="wrist_roll" type="revolute">
    <origin xyz="0.0624157 0 0.0185357" rpy="3.14159 1.5708 0"/>
    <parent link="sts3215_wrist_roll"/>
    <child link="sts3215_gripper"/>
    <axis xyz="0 0 1"/>
    <limit effort="10" velocity="10" lower="-3.14159" upper="3.14159"/>
  </joint>
  <!-- Joint from wrist_mount_link to sts3215_wrist_roll -->
  <joint name="wrist_pitch" type="revolute">
    <origin xyz="0.289534 -0.0335667 0.0154208" rpy="0 -0 -0.122333"/>
    <parent link="wrist_mount_link"/>
    <child link="sts3215_wrist_roll"/>
    <axis xyz="0 0 1"/>
    <limit effort="10" velocity="10" lower="-1.5708" upper="1.5708"/>
  </joint>
  <!-- Joint from shoulder_link to wrist_mount_link -->
  <joint name="elbow_pitch" type="revolute">
    <origin xyz="0.0317 0.23165 0.00195843" rpy="0 -0 0"/>
    <parent link="shoulder_link"/>
    <child link="wrist_mount_link"/>
    <axis xyz="0 0 1"/>
    <limit effort="10" velocity="10" lower="-1.44846" upper="1.69313"/>
  </joint>
  <!-- Joint from base_yaw_link to shoulder_link -->
  <joint name="shoulder_pitch" type="revolute">
    <origin xyz="0.03305 0.0391987 0.0928" rpy="1.5708 -0.122333 -0"/>
    <parent link="base_yaw_link"/>
    <child link="shoulder_link"/>
    <axis xyz="0 0 1"/>
    <limit effort="10" velocity="10" lower="-1.69313" upper="1.44846"/>
  </joint>
  <!-- Joint from base_link to base_yaw_link -->
  <joint name="base_yaw" type="revolute">
    <origin xyz="-0 -0.00753894 0.0278" rpy="0 -0 -1.5708"/>
    <parent link="base_link"/>
    <child link="base_yaw_link"/>
    <axis xyz="0 0 1"/>
    <limit effort="10" velocity="10" lower="-1.5708" upper="1.5708"/>
  </joint>
</robot>
