<?xml version="1.0" ?>
<!-- =================================================================================== -->
<!-- |    This document was autogenerated by xacro from /root/PingTi_Arm_v3_description/urdf/PingTi_Arm_v3.xacro | -->
<!-- |    EDITING THIS FILE BY HAND IS NOT RECOMMENDED                                 | -->
<!-- =================================================================================== -->
<robot name="PingTi_Arm_v3">
  <material name="silver">
    <color rgba="0.700 0.700 0.700 1.000"/>
  </material>
  <transmission name="elbow_pitch_tran">
    <type>transmission_interface/SimpleTransmission</type>
    <joint name="elbow_pitch">
      <hardwareInterface>hardware_interface/EffortJointInterface</hardwareInterface>
    </joint>
    <actuator name="elbow_pitch_actr">
      <hardwareInterface>hardware_interface/EffortJointInterface</hardwareInterface>
      <mechanicalReduction>1</mechanicalReduction>
    </actuator>
  </transmission>
  <transmission name="wrist_pitch_tran">
    <type>transmission_interface/SimpleTransmission</type>
    <joint name="wrist_pitch">
      <hardwareInterface>hardware_interface/EffortJointInterface</hardwareInterface>
    </joint>
    <actuator name="wrist_pitch_actr">
      <hardwareInterface>hardware_interface/EffortJointInterface</hardwareInterface>
      <mechanicalReduction>1</mechanicalReduction>
    </actuator>
  </transmission>
  <transmission name="wrist_roll_tran">
    <type>transmission_interface/SimpleTransmission</type>
    <joint name="wrist_roll">
      <hardwareInterface>hardware_interface/EffortJointInterface</hardwareInterface>
    </joint>
    <actuator name="wrist_roll_actr">
      <hardwareInterface>hardware_interface/EffortJointInterface</hardwareInterface>
      <mechanicalReduction>1</mechanicalReduction>
    </actuator>
  </transmission>
  <transmission name="gripper_moving_tran">
    <type>transmission_interface/SimpleTransmission</type>
    <joint name="gripper_moving">
      <hardwareInterface>hardware_interface/EffortJointInterface</hardwareInterface>
    </joint>
    <actuator name="gripper_moving_actr">
      <hardwareInterface>hardware_interface/EffortJointInterface</hardwareInterface>
      <mechanicalReduction>1</mechanicalReduction>
    </actuator>
  </transmission>
  <transmission name="base_yaw_tran">
    <type>transmission_interface/SimpleTransmission</type>
    <joint name="base_yaw">
      <hardwareInterface>hardware_interface/EffortJointInterface</hardwareInterface>
    </joint>
    <actuator name="base_yaw_actr">
      <hardwareInterface>hardware_interface/EffortJointInterface</hardwareInterface>
      <mechanicalReduction>1</mechanicalReduction>
    </actuator>
  </transmission>
  <transmission name="shoulder_pitch_tran">
    <type>transmission_interface/SimpleTransmission</type>
    <joint name="shoulder_pitch">
      <hardwareInterface>hardware_interface/EffortJointInterface</hardwareInterface>
    </joint>
    <actuator name="shoulder_pitch_actr">
      <hardwareInterface>hardware_interface/EffortJointInterface</hardwareInterface>
      <mechanicalReduction>1</mechanicalReduction>
    </actuator>
  </transmission>
  <gazebo>
    <plugin filename="libgazebo_ros_control.so" name="control"/>
  </gazebo>
  <gazebo reference="base_link">
    <material>Gazebo/Silver</material>
    <mu1>0.2</mu1>
    <mu2>0.2</mu2>
    <selfCollide>true</selfCollide>
    <gravity>true</gravity>
  </gazebo>
  <gazebo reference="elbow_link_1">
    <material>Gazebo/Silver</material>
    <mu1>0.2</mu1>
    <mu2>0.2</mu2>
    <selfCollide>true</selfCollide>
  </gazebo>
  <gazebo reference="STS3215_wrist_pitch_1">
    <material>Gazebo/Silver</material>
    <mu1>0.2</mu1>
    <mu2>0.2</mu2>
    <selfCollide>true</selfCollide>
  </gazebo>
  <gazebo reference="wrist_link_1">
    <material>Gazebo/Silver</material>
    <mu1>0.2</mu1>
    <mu2>0.2</mu2>
    <selfCollide>true</selfCollide>
  </gazebo>
  <gazebo reference="STS3215_wrist_roll_1">
    <material>Gazebo/Silver</material>
    <mu1>0.2</mu1>
    <mu2>0.2</mu2>
    <selfCollide>true</selfCollide>
  </gazebo>
  <gazebo reference="gripper_mount_1">
    <material>Gazebo/Silver</material>
    <mu1>0.2</mu1>
    <mu2>0.2</mu2>
    <selfCollide>true</selfCollide>
  </gazebo>
  <gazebo reference="STS3215_gripper_1">
    <material>Gazebo/Silver</material>
    <mu1>0.2</mu1>
    <mu2>0.2</mu2>
    <selfCollide>true</selfCollide>
  </gazebo>
  <gazebo reference="moving_gripper_1">
    <material>Gazebo/Silver</material>
    <mu1>0.2</mu1>
    <mu2>0.2</mu2>
    <selfCollide>true</selfCollide>
  </gazebo>
  <gazebo reference="wrist_mount_link_1">
    <material>Gazebo/Silver</material>
    <mu1>0.2</mu1>
    <mu2>0.2</mu2>
    <selfCollide>true</selfCollide>
  </gazebo>
  <gazebo reference="STS3215_base_yaw_1">
    <material>Gazebo/Silver</material>
    <mu1>0.2</mu1>
    <mu2>0.2</mu2>
    <selfCollide>true</selfCollide>
  </gazebo>
  <gazebo reference="base_yaw_link_1">
    <material>Gazebo/Silver</material>
    <mu1>0.2</mu1>
    <mu2>0.2</mu2>
    <selfCollide>true</selfCollide>
  </gazebo>
  <gazebo reference="STS3215_shoulder_pitch_1_1">
    <material>Gazebo/Silver</material>
    <mu1>0.2</mu1>
    <mu2>0.2</mu2>
    <selfCollide>true</selfCollide>
  </gazebo>
  <gazebo reference="STS3215_shoulder_pitch_2_1">
    <material>Gazebo/Silver</material>
    <mu1>0.2</mu1>
    <mu2>0.2</mu2>
    <selfCollide>true</selfCollide>
  </gazebo>
  <gazebo reference="shoulder_link_1">
    <material>Gazebo/Silver</material>
    <mu1>0.2</mu1>
    <mu2>0.2</mu2>
    <selfCollide>true</selfCollide>
  </gazebo>
  <gazebo reference="STS3215_elbow_pitch_1_1">
    <material>Gazebo/Silver</material>
    <mu1>0.2</mu1>
    <mu2>0.2</mu2>
    <selfCollide>true</selfCollide>
  </gazebo>
  <gazebo reference="STS3215_elbow_pitch_2_1">
    <material>Gazebo/Silver</material>
    <mu1>0.2</mu1>
    <mu2>0.2</mu2>
    <selfCollide>true</selfCollide>
  </gazebo>
  <link name="base_link">
    <inertial>
      <origin rpy="0 0 0" xyz="-3.2942227991692706e-06 -0.016410113639789673 0.025524321515390098"/>
      <mass value="1.1606702094747876"/>
      <inertia ixx="0.001182" ixy="-0.0" ixz="0.0" iyy="0.001221" iyz="-0.000216" izz="0.001296"/>
    </inertial>
    <visual>
      <origin rpy="0 0 0" xyz="0 0 0"/>
      <geometry>
        <mesh filename="meshes/base_link.stl" scale="0.001 0.001 0.001"/>
      </geometry>
      <material name="silver"/>
    </visual>
    <collision>
      <origin rpy="0 0 0" xyz="0 0 0"/>
      <geometry>
        <mesh filename="meshes/base_link.stl" scale="0.001 0.001 0.001"/>
      </geometry>
    </collision>
  </link>
  <link name="elbow_link_1">
    <inertial>
      <origin rpy="0 0 0" xyz="-0.006368202700747123 -0.13257432066234234 -0.000710253994771759"/>
      <mass value="1.3232321824941673"/>
      <inertia ixx="0.009536" ixy="0.001261" ixz="7e-06" iyy="0.001028" iyz="-4.6e-05" izz="0.010469"/>
    </inertial>
    <visual>
      <origin rpy="0 0 0" xyz="-0.052878 0.100187 -0.3528"/>
      <geometry>
        <mesh filename="meshes/elbow_link_1.stl" scale="0.001 0.001 0.001"/>
      </geometry>
      <material name="silver"/>
    </visual>
    <collision>
      <origin rpy="0 0 0" xyz="-0.052878 0.100187 -0.3528"/>
      <geometry>
        <mesh filename="meshes/elbow_link_1.stl" scale="0.001 0.001 0.001"/>
      </geometry>
    </collision>
  </link>
  <link name="STS3215_wrist_pitch_1">
    <inertial>
      <origin rpy="0 0 0" xyz="-0.015103902665090832 -0.015364326843161913 -2.529961420916216e-07"/>
      <mass value="0.2843033831904074"/>
      <inertia ixx="6.1e-05" ixy="4e-06" ixz="-0.0" iyy="4e-05" iyz="-0.0" izz="7.3e-05"/>
    </inertial>
    <visual>
      <origin rpy="0 0 0" xyz="-0.088612 0.364006 -0.355125"/>
      <geometry>
        <mesh filename="meshes/STS3215_wrist_pitch_1.stl" scale="0.001 0.001 0.001"/>
      </geometry>
      <material name="silver"/>
    </visual>
    <collision>
      <origin rpy="0 0 0" xyz="-0.088612 0.364006 -0.355125"/>
      <geometry>
        <mesh filename="meshes/STS3215_wrist_pitch_1.stl" scale="0.001 0.001 0.001"/>
      </geometry>
    </collision>
  </link>
  <link name="wrist_link_1">
    <inertial>
      <origin rpy="0 0 0" xyz="0.019701433146455137 -0.022957641297722542 -5.135733105687823e-05"/>
      <mass value="0.2392168278135931"/>
      <inertia ixx="0.000118" ixy="-8e-06" ixz="-0.0" iyy="0.000123" iyz="0.0" izz="0.0002"/>
    </inertial>
    <visual>
      <origin rpy="0 0 0" xyz="-0.056252 0.395423 -0.354675"/>
      <geometry>
        <mesh filename="meshes/wrist_link_1.stl" scale="0.001 0.001 0.001"/>
      </geometry>
      <material name="silver"/>
    </visual>
    <collision>
      <origin rpy="0 0 0" xyz="-0.056252 0.395423 -0.354675"/>
      <geometry>
        <mesh filename="meshes/wrist_link_1.stl" scale="0.001 0.001 0.001"/>
      </geometry>
    </collision>
  </link>
  <link name="STS3215_wrist_roll_1">
    <inertial>
      <origin rpy="0 0 0" xyz="-0.008933246759550137 -0.020582128831145963 -2.5299615225016225e-07"/>
      <mass value="0.2843033831904074"/>
      <inertia ixx="4e-05" ixy="-4e-06" ixz="0.0" iyy="6.1e-05" iyz="-0.0" izz="7.3e-05"/>
    </inertial>
    <visual>
      <origin rpy="0 0 0" xyz="-0.078363 0.413656 -0.354675"/>
      <geometry>
        <mesh filename="meshes/STS3215_wrist_roll_1.stl" scale="0.001 0.001 0.001"/>
      </geometry>
      <material name="silver"/>
    </visual>
    <collision>
      <origin rpy="0 0 0" xyz="-0.078363 0.413656 -0.354675"/>
      <geometry>
        <mesh filename="meshes/STS3215_wrist_roll_1.stl" scale="0.001 0.001 0.001"/>
      </geometry>
    </collision>
  </link>
  <link name="gripper_mount_1">
    <inertial>
      <origin rpy="0 0 0" xyz="0.0026773059376802855 -0.020173178230651845 -0.01565257096694167"/>
      <mass value="0.44698022927880193"/>
      <inertia ixx="0.000327" ixy="3.1e-05" ixz="7e-06" iyy="0.000172" iyz="-5.5e-05" izz="0.000301"/>
    </inertial>
    <visual>
      <origin rpy="0 0 0" xyz="-0.087531 0.451084 -0.355125"/>
      <geometry>
        <mesh filename="meshes/gripper_mount_1.stl" scale="0.001 0.001 0.001"/>
      </geometry>
      <material name="silver"/>
    </visual>
    <collision>
      <origin rpy="0 0 0" xyz="-0.087531 0.451084 -0.355125"/>
      <geometry>
        <mesh filename="meshes/gripper_mount_1.stl" scale="0.001 0.001 0.001"/>
      </geometry>
    </collision>
  </link>
  <link name="STS3215_gripper_1">
    <inertial>
      <origin rpy="0 0 0" xyz="0.00012461197605628804 2.539181574140459e-05 0.02239868354094854"/>
      <mass value="0.2843033831904074"/>
      <inertia ixx="6.2e-05" ixy="-2e-06" ixz="-1e-06" iyy="7.3e-05" iyz="-0.0" izz="4e-05"/>
    </inertial>
    <visual>
      <origin rpy="0 0 0" xyz="-0.088124 0.465652 -0.338236"/>
      <geometry>
        <mesh filename="meshes/STS3215_gripper_1.stl" scale="0.001 0.001 0.001"/>
      </geometry>
      <material name="silver"/>
    </visual>
    <collision>
      <origin rpy="0 0 0" xyz="-0.088124 0.465652 -0.338236"/>
      <geometry>
        <mesh filename="meshes/STS3215_gripper_1.stl" scale="0.001 0.001 0.001"/>
      </geometry>
    </collision>
  </link>
  <link name="moving_gripper_1">
    <inertial>
      <origin rpy="0 0 0" xyz="-0.014635153287696837 -0.03276490039211122 -0.0005006987132448737"/>
      <mass value="0.1586808414280307"/>
      <inertia ixx="6.8e-05" ixy="1e-05" ixz="1e-06" iyy="2.6e-05" iyz="-4e-06" izz="8.7e-05"/>
    </inertial>
    <visual>
      <origin rpy="0 0 0" xyz="-0.107931 0.461685 -0.373436"/>
      <geometry>
        <mesh filename="meshes/moving_gripper_1.stl" scale="0.001 0.001 0.001"/>
      </geometry>
      <material name="silver"/>
    </visual>
    <collision>
      <origin rpy="0 0 0" xyz="-0.107931 0.461685 -0.373436"/>
      <geometry>
        <mesh filename="meshes/moving_gripper_1.stl" scale="0.001 0.001 0.001"/>
      </geometry>
    </collision>
  </link>
  <link name="wrist_mount_link_1">
    <inertial>
      <origin rpy="0 0 0" xyz="0.022710832853232152 0.004489136774674496 0.0018439782253499293"/>
      <mass value="0.10853073755546008"/>
      <inertia ixx="2.8e-05" ixy="-6e-06" ixz="-0.0" iyy="5.7e-05" iyz="0.0" izz="4.6e-05"/>
    </inertial>
    <visual>
      <origin rpy="0 0 0" xyz="-0.046447 0.363782 -0.3548"/>
      <geometry>
        <mesh filename="meshes/wrist_mount_link_1.stl" scale="0.001 0.001 0.001"/>
      </geometry>
      <material name="silver"/>
    </visual>
    <collision>
      <origin rpy="0 0 0" xyz="-0.046447 0.363782 -0.3548"/>
      <geometry>
        <mesh filename="meshes/wrist_mount_link_1.stl" scale="0.001 0.001 0.001"/>
      </geometry>
    </collision>
  </link>
  <link name="STS3215_base_yaw_1">
    <inertial>
      <origin rpy="0 0 0" xyz="6.752884890919568e-12 0.02300097243678148 0.00012706492471613318"/>
      <mass value="0.2843033831904074"/>
      <inertia ixx="7.3e-05" ixy="-0.0" ixz="0.0" iyy="4e-05" iyz="1e-06" izz="6.2e-05"/>
    </inertial>
    <visual>
      <origin rpy="0 0 0" xyz="0.0 0.0554 -0.0481"/>
      <geometry>
        <mesh filename="meshes/STS3215_base_yaw_1.stl" scale="0.001 0.001 0.001"/>
      </geometry>
      <material name="silver"/>
    </visual>
    <collision>
      <origin rpy="0 0 0" xyz="0.0 0.0554 -0.0481"/>
      <geometry>
        <mesh filename="meshes/STS3215_base_yaw_1.stl" scale="0.001 0.001 0.001"/>
      </geometry>
    </collision>
  </link>
  <link name="base_yaw_link_1">
    <inertial>
      <origin rpy="0 0 0" xyz="0.0066121913949635435 -0.03322206721963538 0.03628999238042017"/>
      <mass value="0.8041215139582379"/>
      <inertia ixx="0.000599" ixy="-7e-06" ixz="-9e-06" iyy="0.000638" iyz="3.9e-05" izz="0.00036"/>
    </inertial>
    <visual>
      <origin rpy="0 0 0" xyz="0.0 0.0452 -0.0298"/>
      <geometry>
        <mesh filename="meshes/base_yaw_link_1.stl" scale="0.001 0.001 0.001"/>
      </geometry>
      <material name="silver"/>
    </visual>
    <collision>
      <origin rpy="0 0 0" xyz="0.0 0.0452 -0.0298"/>
      <geometry>
        <mesh filename="meshes/base_yaw_link_1.stl" scale="0.001 0.001 0.001"/>
      </geometry>
    </collision>
  </link>
  <link name="STS3215_shoulder_pitch_1_1">
    <inertial>
      <origin rpy="0 0 0" xyz="0.00012478845663918547 2.5028932493509348e-05 0.02239902756319745"/>
      <mass value="0.2843033831904074"/>
      <inertia ixx="6.2e-05" ixy="-2e-06" ixz="-1e-06" iyy="7.3e-05" iyz="-0.0" izz="4e-05"/>
    </inertial>
    <visual>
      <origin rpy="0 0 0" xyz="-0.026994 0.0735 -0.0864"/>
      <geometry>
        <mesh filename="meshes/STS3215_shoulder_pitch_1_1.stl" scale="0.001 0.001 0.001"/>
      </geometry>
      <material name="silver"/>
    </visual>
    <collision>
      <origin rpy="0 0 0" xyz="-0.026994 0.0735 -0.0864"/>
      <geometry>
        <mesh filename="meshes/STS3215_shoulder_pitch_1_1.stl" scale="0.001 0.001 0.001"/>
      </geometry>
    </collision>
  </link>
  <link name="STS3215_shoulder_pitch_2_1">
    <inertial>
      <origin rpy="0 0 0" xyz="-0.00012502334154068304 -2.491142533807278e-05 0.022399027563196117"/>
      <mass value="0.2843033831904074"/>
      <inertia ixx="6.2e-05" ixy="-2e-06" ixz="1e-06" iyy="7.3e-05" iyz="0.0" izz="4e-05"/>
    </inertial>
    <visual>
      <origin rpy="0 0 0" xyz="0.014013 0.081713 -0.0864"/>
      <geometry>
        <mesh filename="meshes/STS3215_shoulder_pitch_2_1.stl" scale="0.001 0.001 0.001"/>
      </geometry>
      <material name="silver"/>
    </visual>
    <collision>
      <origin rpy="0 0 0" xyz="0.014013 0.081713 -0.0864"/>
      <geometry>
        <mesh filename="meshes/STS3215_shoulder_pitch_2_1.stl" scale="0.001 0.001 0.001"/>
      </geometry>
    </collision>
  </link>
  <link name="shoulder_link_1">
    <inertial>
      <origin rpy="0 0 0" xyz="-0.04009132750395989 -0.008071300634675801 0.1143995501318232"/>
      <mass value="1.815312307803877"/>
      <inertia ixx="0.010722" ixy="-0.000321" ixz="0.0" iyy="0.012269" iyz="-6.4e-05" izz="0.001796"/>
    </inertial>
    <visual>
      <origin rpy="0 0 0" xyz="-0.046712 0.069092 -0.12115"/>
      <geometry>
        <mesh filename="meshes/shoulder_link_1.stl" scale="0.001 0.001 0.001"/>
      </geometry>
      <material name="silver"/>
    </visual>
    <collision>
      <origin rpy="0 0 0" xyz="-0.046712 0.069092 -0.12115"/>
      <geometry>
        <mesh filename="meshes/shoulder_link_1.stl" scale="0.001 0.001 0.001"/>
      </geometry>
    </collision>
  </link>
  <link name="STS3215_elbow_pitch_1_1">
    <inertial>
      <origin rpy="0 0 0" xyz="0.004523009170013775 -0.021937733328752027 -2.5253846619444076e-07"/>
      <mass value="0.2843033831904074"/>
      <inertia ixx="6e-05" ixy="5e-06" ixz="-0.0" iyy="4.1e-05" iyz="0.0" izz="7.3e-05"/>
    </inertial>
    <visual>
      <origin rpy="0 0 0" xyz="-0.026159 0.069639 -0.3528"/>
      <geometry>
        <mesh filename="meshes/STS3215_elbow_pitch_1_1.stl" scale="0.001 0.001 0.001"/>
      </geometry>
      <material name="silver"/>
    </visual>
    <collision>
      <origin rpy="0 0 0" xyz="-0.026159 0.069639 -0.3528"/>
      <geometry>
        <mesh filename="meshes/STS3215_elbow_pitch_1_1.stl" scale="0.001 0.001 0.001"/>
      </geometry>
    </collision>
  </link>
  <link name="STS3215_elbow_pitch_2_1">
    <inertial>
      <origin rpy="0 0 0" xyz="0.004274566780616719 -0.02198820720088046 -2.525249563345433e-07"/>
      <mass value="0.2843033831904074"/>
      <inertia ixx="6.1e-05" ixy="4e-06" ixz="-0.0" iyy="4e-05" iyz="-0.0" izz="7.3e-05"/>
    </inertial>
    <visual>
      <origin rpy="0 0 0" xyz="0.014163 0.077714 -0.3528"/>
      <geometry>
        <mesh filename="meshes/STS3215_elbow_pitch_2_1.stl" scale="0.001 0.001 0.001"/>
      </geometry>
      <material name="silver"/>
    </visual>
    <collision>
      <origin rpy="0 0 0" xyz="0.014163 0.077714 -0.3528"/>
      <geometry>
        <mesh filename="meshes/STS3215_elbow_pitch_2_1.stl" scale="0.001 0.001 0.001"/>
      </geometry>
    </collision>
  </link>
  <joint name="elbow_pitch" type="revolute">
    <origin rpy="0 0 0" xyz="0.026719 -0.030548 0.0"/>
    <parent link="STS3215_elbow_pitch_1_1"/>
    <child link="elbow_link_1"/>
    <axis xyz="-0.980528 -0.196381 0.0"/>
    <limit effort="100" lower="-1.570796" upper="1.919862" velocity="100"/>
  </joint>
  <joint name="elbow_wrist_servo_connect" type="fixed">
    <origin rpy="0 0 0" xyz="0.035734 -0.263819 0.002325"/>
    <parent link="elbow_link_1"/>
    <child link="STS3215_wrist_pitch_1"/>
  </joint>
  <joint name="wrist_pitch" type="revolute">
    <origin rpy="0 0 0" xyz="-0.03236 -0.031417 -0.00045"/>
    <parent link="STS3215_wrist_pitch_1"/>
    <child link="wrist_link_1"/>
    <axis xyz="-0.980528 -0.196381 -0.0"/>
    <limit effort="100" lower="-1.919862" upper="1.919862" velocity="100"/>
  </joint>
  <joint name="wrist_wrist_roll_connect" type="fixed">
    <origin rpy="0 0 0" xyz="0.022111 -0.018233 0.0"/>
    <parent link="wrist_link_1"/>
    <child link="STS3215_wrist_roll_1"/>
  </joint>
  <joint name="wrist_roll" type="continuous">
    <origin rpy="0 0 0" xyz="0.009168 -0.037428 0.00045"/>
    <parent link="STS3215_wrist_roll_1"/>
    <child link="gripper_mount_1"/>
    <axis xyz="0.196381 -0.980528 -0.0"/>
  </joint>
  <joint name="wrist_griper_mount_connect" type="fixed">
    <origin rpy="0 0 0" xyz="0.000593 -0.014568 -0.016889"/>
    <parent link="gripper_mount_1"/>
    <child link="STS3215_gripper_1"/>
  </joint>
  <joint name="gripper_moving" type="revolute">
    <origin rpy="0 0 0" xyz="0.019807 0.003967 0.0352"/>
    <parent link="STS3215_gripper_1"/>
    <child link="moving_gripper_1"/>
    <axis xyz="-0.980528 -0.196381 -0.0"/>
    <limit effort="100" lower="-0.20944" upper="1.570796" velocity="100"/>
  </joint>
  <joint name="wrist_mount_connect" type="fixed">
    <origin rpy="0 0 0" xyz="-0.006431 -0.263595 0.002"/>
    <parent link="elbow_link_1"/>
    <child link="wrist_mount_link_1"/>
  </joint>
  <joint name="base_link_mount_connect" type="fixed">
    <origin rpy="0 0 0" xyz="0.0 -0.0554 0.0481"/>
    <parent link="base_link"/>
    <child link="STS3215_base_yaw_1"/>
  </joint>
  <joint name="base_yaw" type="revolute">
    <origin rpy="0 0 0" xyz="0.0 0.0102 -0.0183"/>
    <parent link="STS3215_base_yaw_1"/>
    <child link="base_yaw_link_1"/>
    <axis xyz="0.0 0.0 -1.0"/>
    <limit effort="100" lower="-1.919862" upper="1.919862" velocity="100"/>
  </joint>
  <joint name="base_yaw_link_servo_1_connect" type="fixed">
    <origin rpy="0 0 0" xyz="0.026994 -0.0283 0.0566"/>
    <parent link="base_yaw_link_1"/>
    <child link="STS3215_shoulder_pitch_1_1"/>
  </joint>
  <joint name="base_yaw_link_servo_2_connect" type="fixed">
    <origin rpy="0 0 0" xyz="-0.014013 -0.036513 0.0566"/>
    <parent link="base_yaw_link_1"/>
    <child link="STS3215_shoulder_pitch_2_1"/>
  </joint>
  <joint name="shoulder_pitch" type="revolute">
    <origin rpy="0 0 0" xyz="0.019718 0.004408 0.03475"/>
    <parent link="STS3215_shoulder_pitch_1_1"/>
    <child link="shoulder_link_1"/>
    <axis xyz="0.980528 0.196381 -0.0"/>
    <limit effort="100" lower="-1.745329" upper="1.745329" velocity="100"/>
  </joint>
  <joint name="shoulder_link_servo1_connect" type="fixed">
    <origin rpy="0 0 0" xyz="-0.020553 -0.000547 0.23165"/>
    <parent link="shoulder_link_1"/>
    <child link="STS3215_elbow_pitch_1_1"/>
  </joint>
  <joint name="shoulder_link_servo2_connect" type="fixed">
    <origin rpy="0 0 0" xyz="-0.060875 -0.008622 0.23165"/>
    <parent link="shoulder_link_1"/>
    <child link="STS3215_elbow_pitch_2_1"/>
  </joint>
</robot>
